Workbook
Name Anders: Opzoekblad!$O$3:$O$12
Name Bestuur: Opzoekblad!$F$3:$F$4
Name Bestuurscommissie: Opzoekblad!$J$3:$J$12
Name BIO: Opzoekblad!$Q$4:$Q$34
Name Geleding: Opzoekblad!$D$3:$D$11
Name Kring: Opzoekblad!$I$3:$I$8
Name Kringcoördinatie: Opzoekblad!$H$3:$H$9
Name NASK1: Opzoekblad!$S$3:$S$16
Name NASK2: Opzoekblad!$U$3:$U$16
Name NAT: Opzoekblad!$R$3:$R$15
Name Redactie: Opzoekblad!$L$3:$L$4
Name SCH: Opzoekblad!$T$3:$T$15
Name Sectie: Opzoekblad!$G$3:$G$9
Name TOA: Opzoekblad!$V$3:$V$15
Name Werkgroep: Opzoekblad!$N$3:$N$4

Sheet Instructie
A1: Instructie voor het invullen Reiskostenformulier en presentielijst
A3: Het 'Reiskostenformulier en presentielijst' bestaat uit een aantal tabbladen. Voor de declarant zijn alleen de eerste drie van belang.
A7: In tabblad 'Instructie' staat uitleg over het invullen van het 'Reiskostenformulier en presentielijst'.
A9: Op het tabblad "Gegevens" vult u de gegevens van de geleding van de NVON in. Het tabblad is beveiligd. U kunt alleen de witte vakjes invullen. Met de <tab> of de pijltjes toetsen kunt u naar het volgende witte vakje springen.Uw lidnummer is terug te vinden op uw ledenpas en op het adresetiket bij uw exemplaar van de NVOX/Terugkoppeling.
A10: LET OP de juiste datum; deze moet overeen komen met de datum in de bijbehorende notulen.
A12: Vervolgens selecteert u bij niveau 1 onder welke hoofdpost uw declaratie valt. Zodra u in de witte cel rechts van niveau 1 staat, verschijnt er een dropdown menu. Ga op het driehoekje staan om het drop down menu te laten verschijnen en selecteer de juiste optie
A19: Afhankelijk van de keuze bij niveau 1 verschijnen er bij niveau 2 de opties die daarbij horen.
A20: Hieronder staan de keuzemogelijkheden die in een drop down menu bij niveau 2 verschijnen na het kiezen van een optie bij niveau 1.
A21: niveau 1 | C21: niveau 2
A22: Bestuur | C22: AB - DB
A23: Bestuurscommissie | C23: ARBO - Bovenbw - Duurzaamheid - Financiën - Jong NVON - NVON-Reeks - Onderbw - Ponvon - Vakb.act. - Wet. Oriënt.
A24: Bureau | C24: -
A25: Kring | C25: BIO - NASK1 - NASK2 - NAT - SCH - TOA
A26: Kringcoördinatie | C26: BIO H/V - BIO VMBO - NASK1 VMBO - NASK2 VMBO - NAT H/V - SCH H/V - TOA
A27: Project | C27: In het geval van Project verschijnt er onder het Project een hokje om het projectnummer en de projectnaam in te vullen.
A28: Redactie | C28: NVOX - TK
A29: Sectie | C29: BIO - NAT - NLT - SCH - TECH - TOA - VMBO
A30: Anders | C30: In het geval van Anders verschijnt er onder Anders een hokje om een toelichting te geven.
A32: Alleen als u bij niveau 1 voor "Kring" hebt gekozen en bij niveau 2 een vak hebt geselecteerd, kunt u bij niveau 3 de plaats van de kring selecteren. Let erop: het drop down menu van de plaatsen van de kringen is lang. Het kan zijn dat u in het drop down menu naar beneden moet scrollen.
A33: Als u het werkblad "Gegevens" hebt ingevuld, bewaar deze dan digitaal. Dan hoeft u deze gegevens maar één keer in te vullen (tenzij hierin iets verandert).
A35: Nu kunt u het tabblad "Reiskosten en presentie" invullen.
A36: U vult de naam, postcode en plaats van alle deelnemers in.
A37: In het hokje onder de naam staat een dropdownmenu waarin u kunt aangeven of iemand aan- of afwezig is. Vergeet niet om de alle deelnemers op aanwezig te zetten, want anders worden de vacatiegelden niet berekend. De gegevens van degenen die dit keer afwezig zijn kunt u laten staan. Selecteer in het dropdownmenu dan wel afwezig en let er op dat dit ook wordt aangegeven in de bijbehorende notulen.
A38: LET OP: de deelnemers volgens de presentielijst moeten overeen komen met de deelnemers volgens de notulen.
A39: In het hokje onder voorzitter/notulist/GOVAK kunt u aangeven of de aanwezige de voorzitter, notulist of een medewerker die valt onder de GOVAK-regeling is. De voorzitter en de notulist ontvangen €17 vergoeding in verband met hun functie, bovenop de €18 aan vacatiegelden die elke deelnemer ontvangt. Een medewerker die valt onder de GOVAK regeling ontvangt alleen reiskosten.
A40: Het IBAN bankrekening nummer moet in het format NLXX XXXX XXXX XXXX XX worden opgegeven. In de eerste vier hokjes van het bankrekeningnummer passen 4 tekens, in het laatste hokje 2 tekens.
A42: U mailt de ondertekende 'Reiskostenformulier en presentielijst' spreadsheet, samen met de notulen van de vergadering naar de financiële administratie. Uitprinten en opsturen van het 'Reiskostenformulier en presentielijst' is dus niet meer nodig!
A44: De onderliggende stukken (facturen, bonnen, betalingsbewijzen e.d.) mailt u naar uw budgethouder. Als u deze alleen op papier hebt ontvangen, scan of fotografeer deze dan en mail ze dan naar uw budgethouder. Controleer of digitale gescande of gefotografeerde stukken goed leesbaar zijn.
A46: LET OP: | B46: alle pagina's staan al correct ingesteld en beveiligd. U kunt hier niks aan veranderen. Mocht dit om wat voor reden toch nodig zijn, neemt u dan contact op met de financiële administratie.
A50: Voor vragen over het declareren, invullen van het formulier en overige vragen kunt u de financiële administratie bellen op maandag t/m vrijdag tussen 9.00 en 12.30 uur. Telefoonnumnmer 0522-243347 of mailen naar boekhouder@nvon.nl
A52: Adres : | C52: Financiële Administratie NVON
C53: Dokter van Deenweg 162
C54: 8025 BM Zwolle

Sheet Gegevens
B1: Gegevens
A4: Inzender: | B4: Freek Pols | E4: Telefoon / 06-nr: | G4: 621153564 | I4: Lidnr:
A7: Gelegenheid: | B7: Vergadering boek Pocketdemo's | G7: Plaats: | H7: Online
A9: Datum:
A11: Niveau 1 | B11: Bestuurscommissie | D11: Niveau 2 | F11: NVON-Reeks | H11: Niveau 3
A12: =IF(B11="project","Projectnummer en naam:",IF(B11="Anders","Toelichting:",""))
A14: Naam budgethouder voor akkoord: | D14: Huib van Drooge | G14: Handtekening (digitaal indien mogelijk):

Sheet Reiskosten en presentie
C1: Reiskostenformulier en presentielijst | M1: 1) Aantal kilometers o.b.v. heen- en terugreis; vergoeding per km € 0,23 | S1: aanwezig | T1: voorzitter
M2: 2) Openbaar vervoer o.b.v. heen- en terugreis per 2e klas | S2: afwezig | T2: notulist | U2: 18
B3: Naam | C3: Postcode | D3: Woonplaats | E3: Voorzitter / Notulist / GOVAK | F3: Vergoeding vz./not. | G3: Aantal km | H3: Openb.verv. | I3: Parkeerkn. | J3: Subtotaal | K3: Vacatiegeld | L3: Totaal in € | M3: 3) Parkeerkosten boven € 5 -> origineel bewijs opsturen naar boekhouder; maximale vergoeding per keer € 20 | T3: GOVAK_medewerker | U3: 35
B4: Freek Pols | C4: 2645 GK | D4: Delfgauw | E4: voorzitter | F4: =IF(OR(B5="afwezig",B5="",E4="GOVAK_medewerker",E4=""),0,IF(OR(E4="voorzitter",E4="notulist"),17)) -> 0 | J4: =IF(OR(B5="afwezig",B5=""),0,0.23*G4+H4+I4) -> 0 | K4: =IF(OR(E4="GOVAK_medewerker",B5="afwezig",B5=""),0,18) -> 0 | L4: =F4+J4+K4 -> 0
C5: IBAN bankrekeningnummer | E5: NL42 | F5: INGB | G5: 0007 | H5: 9483 | I5: 17
B6: Ed van den Berg | E6: notulist | F6: =IF(OR(B7="afwezig",B7="",E6="GOVAK_medewerker",E6=""),0,IF(OR(E6="voorzitter",E6="notulist"),17)) -> 0 | J6: =IF(OR(B7="afwezig",B7=""),0,0.23*G6+H6+I6) -> 0 | K6: =IF(OR(E6="GOVAK_medewerker",B7="afwezig",B7=""),0,18) -> 0 | L6: =F6+J6+K6 -> 0
C7: IBAN bankrekeningnummer | E7: NLXX | F7: XXXX | G7: XXXX | H7: XXXX | I7: XX
F8: =IF(OR(B9="afwezig",B9="",E8="GOVAK_medewerker",E8=""),0,IF(OR(E8="voorzitter",E8="notulist"),17)) -> 0 | J8: =IF(OR(B9="afwezig",B9=""),0,0.23*G8+H8+I8) -> 0 | K8: =IF(OR(E8="GOVAK_medewerker",B9="afwezig",B9=""),0,18) -> 0 | L8: =F8+J8+K8 -> 0
C9: IBAN bankrekeningnummer | E9: NLXX | F9: XXXX | G9: XXXX | H9: XXXX | I9: XX
F10: =IF(OR(B11="afwezig",B11="",E10="GOVAK_medewerker",E10=""),0,IF(OR(E10="voorzitter",E10="notulist"),17)) -> 0 | J10: =IF(OR(B11="afwezig",B11=""),0,0.23*G10+H10+I10) -> 0 | K10: =IF(OR(E10="GOVAK_medewerker",B11="afwezig",B11=""),0,18) -> 0 | L10: =F10+J10+K10 -> 0
C11: IBAN bankrekeningnummer | E11: NLXX | F11: XXXX | G11: XXXX | H11: XXXX | I11: XX
F12: =IF(OR(B13="afwezig",B13="",E12="GOVAK_medewerker",E12=""),0,IF(OR(E12="voorzitter",E12="notulist"),17)) -> 0 | J12: =IF(OR(B13="afwezig",B13=""),0,0.23*G12+H12+I12) -> 0 | K12: =IF(OR(E12="GOVAK_medewerker",B13="afwezig",B13=""),0,18) -> 0 | L12: =F12+J12+K12 -> 0
C13: IBAN bankrekeningnummer | E13: NLXX | F13: XXXX | G13: XXXX | H13: XXXX | I13: XX
F14: =IF(OR(B15="afwezig",B15="",E14="GOVAK_medewerker",E14=""),0,IF(OR(E14="voorzitter",E14="notulist"),17)) -> 0 | J14: =IF(OR(B15="afwezig",B15=""),0,0.23*G14+H14+I14) -> 0 | K14: =IF(OR(E14="GOVAK_medewerker",B15="afwezig",B15=""),0,18) -> 0 | L14: =F14+J14+K14 -> 0
C15: IBAN bankrekeningnummer | E15: NLXX | F15: XXXX | G15: XXXX | H15: XXXX | I15: XX
F16: =IF(OR(B17="afwezig",B17="",E16="GOVAK_medewerker",E16=""),0,IF(OR(E16="voorzitter",E16="notulist"),17)) -> 0 | J16: =IF(OR(B17="afwezig",B17=""),0,0.23*G16+H16+I16) -> 0 | K16: =IF(OR(E16="GOVAK_medewerker",B17="afwezig",B17=""),0,18) -> 0 | L16: =F16+J16+K16 -> 0
C17: IBAN bankrekeningnummer | E17: NLXX | F17: XXXX | G17: XXXX | H17: XXXX | I17: XX
F18: =IF(OR(B19="afwezig",B19="",E18="GOVAK_medewerker",E18=""),0,IF(OR(E18="voorzitter",E18="notulist"),17)) -> 0 | J18: =IF(OR(B19="afwezig",B19=""),0,0.23*G18+H18+I18) -> 0 | K18: =IF(OR(E18="GOVAK_medewerker",B19="afwezig",B19=""),0,18) -> 0 | L18: =F18+J18+K18 -> 0
C19: IBAN bankrekeningnummer | E19: NLXX | F19: XXXX | G19: XXXX | H19: XXXX | I19: XX
F20: =IF(OR(B21="afwezig",B21="",E20="GOVAK_medewerker",E20=""),0,IF(OR(E20="voorzitter",E20="notulist"),17)) -> 0 | J20: =IF(OR(B21="afwezig",B21=""),0,0.23*G20+H20+I20) -> 0 | K20: =IF(OR(E20="GOVAK_medewerker",B21="afwezig",B21=""),0,18) -> 0 | L20: =F20+J20+K20 -> 0
C21: IBAN bankrekeningnummer | E21: NLXX | F21: XXXX | G21: XXXX | H21: XXXX | I21: XX
F22: =IF(OR(B23="afwezig",B23="",E22="GOVAK_medewerker",E22=""),0,IF(OR(E22="voorzitter",E22="notulist"),17)) -> 0 | J22: =IF(OR(B23="afwezig",B23=""),0,0.23*G22+H22+I22) -> 0 | K22: =IF(OR(E22="GOVAK_medewerker",B23="afwezig",B23=""),0,18) -> 0 | L22: =F22+J22+K22 -> 0
C23: IBAN bankrekeningnummer | E23: NLXX | F23: XXXX | G23: XXXX | H23: XXXX | I23: XX
F24: =IF(OR(B25="afwezig",B25="",E24="GOVAK_medewerker",E24=""),0,IF(OR(E24="voorzitter",E24="notulist"),17)) -> 0 | J24: =IF(OR(B25="afwezig",B25=""),0,0.23*G24+H24+I24) -> 0 | K24: =IF(OR(E24="GOVAK_medewerker",B25="afwezig",B25=""),0,18) -> 0 | L24: =F24+J24+K24 -> 0
C25: IBAN bankrekeningnummer | E25: NLXX | F25: XXXX | G25: XXXX | H25: XXXX | I25: XX
F26: =IF(OR(B27="afwezig",B27="",E26="GOVAK_medewerker",E26=""),0,IF(OR(E26="voorzitter",E26="notulist"),17)) -> 0 | J26: =IF(OR(B27="afwezig",B27=""),0,0.23*G26+H26+I26) -> 0 | K26: =IF(OR(E26="GOVAK_medewerker",B27="afwezig",B27=""),0,18) -> 0 | L26: =F26+J26+K26 -> 0
C27: IBAN bankrekeningnummer | E27: NLXX | F27: XXXX | G27: XXXX | H27: XXXX | I27: XX
F28: =IF(OR(B29="afwezig",B29="",E28="GOVAK_medewerker",E28=""),0,IF(OR(E28="voorzitter",E28="notulist"),17)) -> 0 | J28: =IF(OR(B29="afwezig",B29=""),0,0.23*G28+H28+I28) -> 0 | K28: =IF(OR(E28="GOVAK_medewerker",B29="afwezig",B29=""),0,18) -> 0 | L28: =F28+J28+K28 -> 0
C29: IBAN bankrekeningnummer | E29: NLXX | F29: XXXX | G29: XXXX | H29: XXXX | I29: XX
F30: =IF(OR(B31="afwezig",B31="",E30="GOVAK_medewerker",E30=""),0,IF(OR(E30="voorzitter",E30="notulist"),17)) -> 0 | J30: =IF(OR(B31="afwezig",B31=""),0,0.23*G30+H30+I30) -> 0 | K30: =IF(OR(E30="GOVAK_medewerker",B31="afwezig",B31=""),0,18) -> 0 | L30: =F30+J30+K30 -> 0
C31: IBAN bankrekeningnummer | E31: NLXX | F31: XXXX | G31: XXXX | H31: XXXX | I31: XX
F32: =IF(OR(B33="afwezig",B33="",E32="GOVAK_medewerker",E32=""),0,IF(OR(E32="voorzitter",E32="notulist"),17)) -> 0 | J32: =IF(OR(B33="afwezig",B33=""),0,0.23*G32+H32+I32) -> 0 | K32: =IF(OR(E32="GOVAK_medewerker",B33="afwezig",B33=""),0,18) -> 0 | L32: =F32+J32+K32 -> 0
C33: IBAN bankrekeningnummer | E33: NLXX | F33: XXXX | G33: XXXX | H33: XXXX | I33: XX
F34: =IF(OR(B35="afwezig",B35="",E34="GOVAK_medewerker",E34=""),0,IF(OR(E34="voorzitter",E34="notulist"),17)) -> 0 | J34: =IF(OR(B35="afwezig",B35=""),0,0.23*G34+H34+I34) -> 0 | K34: =IF(OR(E34="GOVAK_medewerker",B35="afwezig",B35=""),0,18) -> 0 | L34: =F34+J34+K34 -> 0
C35: IBAN bankrekeningnummer | E35: NLXX | F35: XXXX | G35: XXXX | H35: XXXX | I35: XX
F36: =IF(OR(B37="afwezig",B37="",E36="GOVAK_medewerker",E36=""),0,IF(OR(E36="voorzitter",E36="notulist"),17)) -> 0 | J36: =IF(OR(B37="afwezig",B37=""),0,0.23*G36+H36+I36) -> 0 | K36: =IF(OR(E36="GOVAK_medewerker",B37="afwezig",B37=""),0,18) -> 0 | L36: =F36+J36+K36 -> 0
C37: IBAN bankrekeningnummer | E37: NLXX | F37: XXXX | G37: XXXX | H37: XXXX | I37: XX
F38: =IF(OR(B39="afwezig",B39="",E38="GOVAK_medewerker",E38=""),0,IF(OR(E38="voorzitter",E38="notulist"),17)) -> 0 | J38: =IF(OR(B39="afwezig",B39=""),0,0.23*G38+H38+I38) -> 0 | K38: =IF(OR(E38="GOVAK_medewerker",B39="afwezig",B39=""),0,18) -> 0 | L38: =F38+J38+K38 -> 0
C39: IBAN bankrekeningnummer | E39: NLXX | F39: XXXX | G39: XXXX | H39: XXXX | I39: XX
F40: =IF(OR(B41="afwezig",B41="",E40="GOVAK_medewerker",E40=""),0,IF(OR(E40="voorzitter",E40="notulist"),17)) -> 0 | J40: =IF(OR(B41="afwezig",B41=""),0,0.23*G40+H40+I40) -> 0 | K40: =IF(OR(E40="GOVAK_medewerker",B41="afwezig",B41=""),0,18) -> 0 | L40: =F40+J40+K40 -> 0
...

Sheet Voor boekhouder
B2: Declaratie van: | D2: =IF(Gegevens!B11=0,"",Gegevens!B11) -> Bestuurscommissie | E2: =IF(Gegevens!F11=0,"",Gegevens!F11) -> NVON-Reeks | F2: =IF(Gegevens!J11=0,"",Gegevens!J11)
B3: Gelegenheid: | D3: =IF(Gegevens!B7=0,"",Gegevens!B7) -> Vergadering boek Pocketdemo's
B4: Plaats: | D4: =IF(Gegevens!H7=0,"",Gegevens!H7) -> Online
B5: Datum: | D5: =IF(Gegevens!B9=0,"",Gegevens!B9) | F5: Boekstuknummer:
B6: Budgethouder: | D6: =IF(Gegevens!D14=0,"",Gegevens!D14) -> Huib van Drooge
A8: =IF(OR('Reiskosten en presentie'!B5="afwezig",'Reiskosten en presentie'!B5="",'Reiskosten en presentie'!B4=""),"","1") | B8: =IF(OR('Reiskosten en presentie'!B5="afwezig",'Reiskosten en presentie'!B5="",'Reiskosten en presentie'!B4=""),"","Naam:") | D8: =IF(OR('Reiskosten en presentie'!B5="afwezig",'Reiskosten en presentie'!B5="",'Reiskosten en presentie'!B4=""),"",'Reiskosten en presentie'!B4)
B9: =IF(OR('Reiskosten en presentie'!B5="afwezig",'Reiskosten en presentie'!B5="",'Reiskosten en presentie'!B4=""),"","Bankrekeningnummer:") | D9: =IF(OR('Reiskosten en presentie'!B5="afwezig",'Reiskosten en presentie'!B5="",'Reiskosten en presentie'!B4=""),"",'Reiskosten en presentie'!E5) | E9: =IF(OR('Reiskosten en presentie'!B5="afwezig",'Reiskosten en presentie'!B5="",'Reiskosten en presentie'!B4=""),"",'Reiskosten en presentie'!F5) | F9: =IF(OR('Reiskosten en presentie'!B5="afwezig",'Reiskosten en presentie'!B5="",'Reiskosten en presentie'!B4=""),"",'Reiskosten en presentie'!G5) | G9: =IF(OR('Reiskosten en presentie'!B5="afwezig",'Reiskosten en presentie'!B5="",'Reiskosten en presentie'!B4=""),"",'Reiskosten en presentie'!H5) | H9: =IF(OR('Reiskosten en presentie'!B5="afwezig",'Reiskosten en presentie'!B5="",'Reiskosten en presentie'!B4=""),"",'Reiskosten en presentie'!I5) | I9: =IF(OR('Reiskosten en presentie'!B5="afwezig",'Reiskosten en presentie'!B5="",'Reiskosten en presentie'!B4=""),"","□") | J9: =IF(OR('Reiskosten en presentie'!B5="afwezig",'Reiskosten en presentie'!B5="",'Reiskosten en presentie'!B4=""),"","controle")
B10: =IF(OR('Reiskosten en presentie'!B5="afwezig",'Reiskosten en presentie'!B5="",'Reiskosten en presentie'!B4=""),"","0001 Kantoorbehoeften") | D10: =IF(OR('Reiskosten en presentie'!B5="afwezig",'Reiskosten en presentie'!B5="",'Reiskosten en presentie'!B4=""),"",'Reiskosten en presentie'!F4+'Reiskosten en presentie'!K4)
B11: =IF(OR('Reiskosten en presentie'!B5="afwezig",'Reiskosten en presentie'!B5="",'Reiskosten en presentie'!B4=""),"","0008 Reiskosten") | D11: =IF(OR('Reiskosten en presentie'!B5="afwezig",'Reiskosten en presentie'!B5="",'Reiskosten en presentie'!B4=""),"",'Reiskosten en presentie'!J4)
A13: =IF(OR('Reiskosten en presentie'!B7="afwezig",'Reiskosten en presentie'!B7="",'Reiskosten en presentie'!B6=""),"","2") | B13: =IF(OR('Reiskosten en presentie'!B7="afwezig",'Reiskosten en presentie'!B7="",'Reiskosten en presentie'!B6=""),"","Naam:") | D13: =IF(OR('Reiskosten en presentie'!B7="afwezig",'Reiskosten en presentie'!B7="",'Reiskosten en presentie'!B6=""),"",'Reiskosten en presentie'!B6)
B14: =IF(OR('Reiskosten en presentie'!B7="afwezig",'Reiskosten en presentie'!B7="",'Reiskosten en presentie'!B6=""),"","Bankrekeningnummer:") | D14: =IF(OR('Reiskosten en presentie'!B7="afwezig",'Reiskosten en presentie'!B7="",'Reiskosten en presentie'!B6=""),"",'Reiskosten en presentie'!E7) | E14: =IF(OR('Reiskosten en presentie'!B7="afwezig",'Reiskosten en presentie'!B7="",'Reiskosten en presentie'!B6=""),"",'Reiskosten en presentie'!F7) | F14: =IF(OR('Reiskosten en presentie'!B7="afwezig",'Reiskosten en presentie'!B7="",'Reiskosten en presentie'!B6=""),"",'Reiskosten en presentie'!G7) | G14: =IF(OR('Reiskosten en presentie'!B7="afwezig",'Reiskosten en presentie'!B7="",'Reiskosten en presentie'!B6=""),"",'Reiskosten en presentie'!H7) | H14: =IF(OR('Reiskosten en presentie'!B7="afwezig",'Reiskosten en presentie'!B7="",'Reiskosten en presentie'!B6=""),"",'Reiskosten en presentie'!I7) | I14: =IF(OR('Reiskosten en presentie'!B7="afwezig",'Reiskosten en presentie'!B7="",'Reiskosten en presentie'!B6=""),"","□") | J14: =IF(OR('Reiskosten en presentie'!B7="afwezig",'Reiskosten en presentie'!B7="",'Reiskosten en presentie'!B6=0),"","controle")
B15: =IF(OR('Reiskosten en presentie'!B7="afwezig",'Reiskosten en presentie'!B7="",'Reiskosten en presentie'!B6=""),"","0001 Kantoorbehoeften") | D15: =IF(OR('Reiskosten en presentie'!B7="afwezig",'Reiskosten en presentie'!B7="",'Reiskosten en presentie'!B6=""),"",'Reiskosten en presentie'!F6+'Reiskosten en presentie'!K6)
B16: =IF(OR('Reiskosten en presentie'!B7="afwezig",'Reiskosten en presentie'!B7="",'Reiskosten en presentie'!B6=""),"","0008 Reiskosten") | D16: =IF(OR('Reiskosten en presentie'!B7="afwezig",'Reiskosten en presentie'!B7="",'Reiskosten en presentie'!B6=""),"",'Reiskosten en presentie'!J6)
A18: =IF(OR('Reiskosten en presentie'!B9="afwezig",'Reiskosten en presentie'!B9="",'Reiskosten en presentie'!B8=""),"","3") | B18: =IF(OR('Reiskosten en presentie'!B9="afwezig",'Reiskosten en presentie'!B9="",'Reiskosten en presentie'!B8=""),"","Naam:") | D18: =IF(OR('Reiskosten en presentie'!B9="afwezig",'Reiskosten en presentie'!B9="",'Reiskosten en presentie'!B8=""),"",'Reiskosten en presentie'!B8)
B19: =IF(OR('Reiskosten en presentie'!B9="afwezig",'Reiskosten en presentie'!B9="",'Reiskosten en presentie'!B8=""),"","Bankrekeningnummer:") | D19: =IF(OR('Reiskosten en presentie'!B9="afwezig",'Reiskosten en presentie'!B9="",'Reiskosten en presentie'!B8=""),"",'Reiskosten en presentie'!E9) | E19: =IF(OR('Reiskosten en presentie'!B9="afwezig",'Reiskosten en presentie'!B9="",'Reiskosten en presentie'!B8=""),"",'Reiskosten en presentie'!F9) | F19: =IF(OR('Reiskosten en presentie'!B9="afwezig",'Reiskosten en presentie'!B9="",'Reiskosten en presentie'!B8=0),"",'Reiskosten en presentie'!G9) | G19: =IF(OR('Reiskosten en presentie'!B9="afwezig",'Reiskosten en presentie'!B9="",'Reiskosten en presentie'!B8=0),"",'Reiskosten en presentie'!H9) | H19: =IF(OR('Reiskosten en presentie'!B9="afwezig",'Reiskosten en presentie'!B9="",'Reiskosten en presentie'!B8=0),"",'Reiskosten en presentie'!I9) | I19: =IF(OR('Reiskosten en presentie'!B9="afwezig",'Reiskosten en presentie'!B9="",'Reiskosten en presentie'!B8=0),"","□") | J19: =IF(OR('Reiskosten en presentie'!B9="afwezig",'Reiskosten en presentie'!B9="",'Reiskosten en presentie'!B8=0),"","controle")
B20: =IF(OR('Reiskosten en presentie'!B9="afwezig",'Reiskosten en presentie'!B9="",'Reiskosten en presentie'!B8=""),"","0001 Kantoorbehoeften") | D20: =IF(OR('Reiskosten en presentie'!B9="afwezig",'Reiskosten en presentie'!B9="",'Reiskosten en presentie'!B8=""),"",'Reiskosten en presentie'!F8+'Reiskosten en presentie'!K8)
B21: =IF(OR('Reiskosten en presentie'!B9="afwezig",'Reiskosten en presentie'!B9="",'Reiskosten en presentie'!B8=""),"","0008 Reiskosten") | D21: =IF(OR('Reiskosten en presentie'!B9="afwezig",'Reiskosten en presentie'!B9="",'Reiskosten en presentie'!B8=""),"",'Reiskosten en presentie'!J8)
A23: =IF(OR('Reiskosten en presentie'!B11="afwezig",'Reiskosten en presentie'!B11="",'Reiskosten en presentie'!B10=""),"","4") | B23: =IF(OR('Reiskosten en presentie'!B11="afwezig",'Reiskosten en presentie'!B11="",'Reiskosten en presentie'!B10=""),"","Naam:") | D23: =IF(OR('Reiskosten en presentie'!B11="afwezig",'Reiskosten en presentie'!B11="",'Reiskosten en presentie'!B10=""),"",'Reiskosten en presentie'!B10)
B24: =IF(OR('Reiskosten en presentie'!B11="afwezig",'Reiskosten en presentie'!B11="",'Reiskosten en presentie'!B10=""),"","Bankrekeningnummer:") | D24: =IF(OR('Reiskosten en presentie'!B11="afwezig",'Reiskosten en presentie'!B11="",'Reiskosten en presentie'!B10=""),"",'Reiskosten en presentie'!E11) | E24: =IF(OR('Reiskosten en presentie'!B11="afwezig",'Reiskosten en presentie'!B11="",'Reiskosten en presentie'!B10=""),"",'Reiskosten en presentie'!F11) | F24: =IF(OR('Reiskosten en presentie'!B11="afwezig",'Reiskosten en presentie'!B11="",'Reiskosten en presentie'!B10=""),"",'Reiskosten en presentie'!G11) | G24: =IF(OR('Reiskosten en presentie'!B11="afwezig",'Reiskosten en presentie'!B11="",'Reiskosten en presentie'!B10=""),"",'Reiskosten en presentie'!H11) | H24: =IF(OR('Reiskosten en presentie'!B11="afwezig",'Reiskosten en presentie'!B11="",'Reiskosten en presentie'!B10=""),"",'Reiskosten en presentie'!I11) | I24: =IF(OR('Reiskosten en presentie'!B11="afwezig",'Reiskosten en presentie'!B11="",'Reiskosten en presentie'!B10=""),"","□") | J24: =IF(OR('Reiskosten en presentie'!B11="afwezig",'Reiskosten en presentie'!B11="",'Reiskosten en presentie'!B10=""),"","controle")
B25: =IF(OR('Reiskosten en presentie'!B11="afwezig",'Reiskosten en presentie'!B11="",'Reiskosten en presentie'!B10=""),"","0001 Kantoorbehoeften") | D25: =IF(OR('Reiskosten en presentie'!B11="afwezig",'Reiskosten en presentie'!B11="",'Reiskosten en presentie'!B10=""),"",'Reiskosten en presentie'!F10+'Reiskosten en presentie'!K10)
B26: =IF(OR('Reiskosten en presentie'!B11="afwezig",'Reiskosten en presentie'!B11="",'Reiskosten en presentie'!B10=""),"","0008 Reiskosten") | D26: =IF(OR('Reiskosten en presentie'!B11="afwezig",'Reiskosten en presentie'!B11="",'Reiskosten en presentie'!B10=""),"",'Reiskosten en presentie'!J10)
A28: =IF(OR('Reiskosten en presentie'!B13="afwezig",'Reiskosten en presentie'!B13="",'Reiskosten en presentie'!B12=""),"","5") | B28: =IF(OR('Reiskosten en presentie'!B13="afwezig",'Reiskosten en presentie'!B13="",'Reiskosten en presentie'!B12=""),"","Naam:") | D28: =IF(OR('Reiskosten en presentie'!B13="afwezig",'Reiskosten en presentie'!B13="",'Reiskosten en presentie'!B12=""),"",'Reiskosten en presentie'!B12)
B29: =IF(OR('Reiskosten en presentie'!B13="afwezig",'Reiskosten en presentie'!B13="",'Reiskosten en presentie'!B12=""),"","Bankrekeningnummer:") | D29: =IF(OR('Reiskosten en presentie'!B13="afwezig",'Reiskosten en presentie'!B13="",'Reiskosten en presentie'!B12=""),"",'Reiskosten en presentie'!E13) | E29: =IF(OR('Reiskosten en presentie'!B13="afwezig",'Reiskosten en presentie'!B13="",'Reiskosten en presentie'!B12=""),"",'Reiskosten en presentie'!F13) | F29: =IF(OR('Reiskosten en presentie'!B13="afwezig",'Reiskosten en presentie'!B13="",'Reiskosten en presentie'!B12=""),"",'Reiskosten en presentie'!G13) | G29: =IF(OR('Reiskosten en presentie'!B13="afwezig",'Reiskosten en presentie'!B13="",'Reiskosten en presentie'!B12=""),"",'Reiskosten en presentie'!H13) | H29: =IF(OR('Reiskosten en presentie'!B13="afwezig",'Reiskosten en presentie'!B13="",'Reiskosten en presentie'!B12=""),"",'Reiskosten en presentie'!I13) | I29: =IF(OR('Reiskosten en presentie'!B13="afwezig",'Reiskosten en presentie'!B13="",'Reiskosten en presentie'!B12=""),"","□") | J29: =IF(OR('Reiskosten en presentie'!B13="afwezig",'Reiskosten en presentie'!B13="",'Reiskosten en presentie'!B12=""),"","controle")
B30: =IF(OR('Reiskosten en presentie'!B13="afwezig",'Reiskosten en presentie'!B13="",'Reiskosten en presentie'!B12=""),"","0001 Kantoorbehoeften") | D30: =IF(OR('Reiskosten en presentie'!B13="afwezig",'Reiskosten en presentie'!B13="",'Reiskosten en presentie'!B12=""),"",'Reiskosten en presentie'!F12+'Reiskosten en presentie'!K12)
B31: =IF(OR('Reiskosten en presentie'!B13="afwezig",'Reiskosten en presentie'!B13="",'Reiskosten en presentie'!B12=""),"","0008 Reiskosten") | D31: =IF(OR('Reiskosten en presentie'!B13="afwezig",'Reiskosten en presentie'!B13="",'Reiskosten en presentie'!B12=""),"",'Reiskosten en presentie'!J12)
A33: =IF(OR('Reiskosten en presentie'!B15="afwezig",'Reiskosten en presentie'!B15="",'Reiskosten en presentie'!B14=""),"","6") | B33: =IF(OR('Reiskosten en presentie'!B15="afwezig",'Reiskosten en presentie'!B15="",'Reiskosten en presentie'!B14=""),"","Naam:") | D33: =IF(OR('Reiskosten en presentie'!B15="afwezig",'Reiskosten en presentie'!B15="",'Reiskosten en presentie'!B14=""),"",'Reiskosten en presentie'!B14)
B34: =IF(OR('Reiskosten en presentie'!B15="afwezig",'Reiskosten en presentie'!B15="",'Reiskosten en presentie'!B14=""),"","Bankrekeningnummer:") | D34: =IF(OR('Reiskosten en presentie'!B15="afwezig",'Reiskosten en presentie'!B15="",'Reiskosten en presentie'!B14=""),"",'Reiskosten en presentie'!E15) | E34: =IF(OR('Reiskosten en presentie'!B15="afwezig",'Reiskosten en presentie'!B15="",'Reiskosten en presentie'!B14=""),"",'Reiskosten en presentie'!F15) | F34: =IF(OR('Reiskosten en presentie'!B15="afwezig",'Reiskosten en presentie'!B15="",'Reiskosten en presentie'!B14=""),"",'Reiskosten en presentie'!G15) | G34: =IF(OR('Reiskosten en presentie'!B15="afwezig",'Reiskosten en presentie'!B15="",'Reiskosten en presentie'!B14=""),"",'Reiskosten en presentie'!H15) | H34: =IF(OR('Reiskosten en presentie'!B15="afwezig",'Reiskosten en presentie'!B15="",'Reiskosten en presentie'!B14=""),"",'Reiskosten en presentie'!I15) | I34: =IF(OR('Reiskosten en presentie'!B15="afwezig",'Reiskosten en presentie'!B15="",'Reiskosten en presentie'!B14=""),"","□") | J34: =IF(OR('Reiskosten en presentie'!B15="afwezig",'Reiskosten en presentie'!B15="",'Reiskosten en presentie'!B14=""),"","controle")
B35: =IF(OR('Reiskosten en presentie'!B15="afwezig",'Reiskosten en presentie'!B15="",'Reiskosten en presentie'!B14=""),"","0001 Kantoorbehoeften") | D35: =IF(OR('Reiskosten en presentie'!B15="afwezig",'Reiskosten en presentie'!B15="",'Reiskosten en presentie'!B14=""),"",'Reiskosten en presentie'!F14+'Reiskosten en presentie'!K14)
B36: =IF(OR('Reiskosten en presentie'!B15="afwezig",'Reiskosten en presentie'!B15="",'Reiskosten en presentie'!B14=""),"","0008 Reiskosten") | D36: =IF(OR('Reiskosten en presentie'!B15="afwezig",'Reiskosten en presentie'!B15="",'Reiskosten en presentie'!B14=""),"",'Reiskosten en presentie'!J14)
A38: =IF(OR('Reiskosten en presentie'!B17="afwezig",'Reiskosten en presentie'!B17="",'Reiskosten en presentie'!B16=""),"","7") | B38: =IF(OR('Reiskosten en presentie'!B17="afwezig",'Reiskosten en presentie'!B17="",'Reiskosten en presentie'!B16=""),"","Naam:") | D38: =IF(OR('Reiskosten en presentie'!B17="afwezig",'Reiskosten en presentie'!B17="",'Reiskosten en presentie'!B16=""),"",'Reiskosten en presentie'!B16)
B39: =IF(OR('Reiskosten en presentie'!B17="afwezig",'Reiskosten en presentie'!B17="",'Reiskosten en presentie'!B16=""),"","Bankrekeningnummer:") | D39: =IF(OR('Reiskosten en presentie'!B17="afwezig",'Reiskosten en presentie'!B17="",'Reiskosten en presentie'!B16=""),"",'Reiskosten en presentie'!E17) | E39: =IF(OR('Reiskosten en presentie'!B17="afwezig",'Reiskosten en presentie'!B17="",'Reiskosten en presentie'!B16=""),"",'Reiskosten en presentie'!F17) | F39: =IF(OR('Reiskosten en presentie'!B17="afwezig",'Reiskosten en presentie'!B17="",'Reiskosten en presentie'!B16=""),"",'Reiskosten en presentie'!G17) | G39: =IF(OR('Reiskosten en presentie'!B17="afwezig",'Reiskosten en presentie'!B17="",'Reiskosten en presentie'!B16=""),"",'Reiskosten en presentie'!H17) | H39: =IF(OR('Reiskosten en presentie'!B17="afwezig",'Reiskosten en presentie'!B17="",'Reiskosten en presentie'!B16=""),"",'Reiskosten en presentie'!I17) | I39: =IF(OR('Reiskosten en presentie'!B17="afwezig",'Reiskosten en presentie'!B17="",'Reiskosten en presentie'!B16=""),"","□") | J39: =IF(OR('Reiskosten en presentie'!B17="afwezig",'Reiskosten en presentie'!B17="",'Reiskosten en presentie'!B16=""),"","controle")
B40: =IF(OR('Reiskosten en presentie'!B17="afwezig",'Reiskosten en presentie'!B17="",'Reiskosten en presentie'!B16=""),"","0001 Kantoorbehoeften") | D40: =IF(OR('Reiskosten en presentie'!B17="afwezig",'Reiskosten en presentie'!B17="",'Reiskosten en presentie'!B16=""),"",'Reiskosten en presentie'!F16+'Reiskosten en presentie'!K16)
B41: =IF(OR('Reiskosten en presentie'!B17="afwezig",'Reiskosten en presentie'!B17="",'Reiskosten en presentie'!B16=""),"","0008 Reiskosten") | D41: =IF(OR('Reiskosten en presentie'!B17="afwezig",'Reiskosten en presentie'!B17="",'Reiskosten en presentie'!B16=""),"",'Reiskosten en presentie'!J16)
A43: =IF(OR('Reiskosten en presentie'!B19="afwezig",'Reiskosten en presentie'!B19="",'Reiskosten en presentie'!B18=""),"","8") | B43: =IF(OR('Reiskosten en presentie'!B19="afwezig",'Reiskosten en presentie'!B19="",'Reiskosten en presentie'!B18=""),"","Naam:") | D43: =IF(OR('Reiskosten en presentie'!B19="afwezig",'Reiskosten en presentie'!B19="",'Reiskosten en presentie'!B18=""),"",'Reiskosten en presentie'!B18)
B44: =IF(OR('Reiskosten en presentie'!B19="afwezig",'Reiskosten en presentie'!B19="",'Reiskosten en presentie'!B18=""),"","Bankrekeningnummer:") | D44: =IF(OR('Reiskosten en presentie'!B19="afwezig",'Reiskosten en presentie'!B19="",'Reiskosten en presentie'!B18=""),"",'Reiskosten en presentie'!E19) | E44: =IF(OR('Reiskosten en presentie'!B19="afwezig",'Reiskosten en presentie'!B19="",'Reiskosten en presentie'!B18=""),"",'Reiskosten en presentie'!F19) | F44: =IF(OR('Reiskosten en presentie'!B19="afwezig",'Reiskosten en presentie'!B19="",'Reiskosten en presentie'!B18=""),"",'Reiskosten en presentie'!G19) | G44: =IF(OR('Reiskosten en presentie'!B19="afwezig",'Reiskosten en presentie'!B19="",'Reiskosten en presentie'!B18=""),"",'Reiskosten en presentie'!H19) | H44: =IF(OR('Reiskosten en presentie'!B19="afwezig",'Reiskosten en presentie'!B19="",'Reiskosten en presentie'!B18=""),"",'Reiskosten en presentie'!I19) | I44: =IF(OR('Reiskosten en presentie'!B19="afwezig",'Reiskosten en presentie'!B19="",'Reiskosten en presentie'!B18=""),"","□") | J44: =IF(OR('Reiskosten en presentie'!B19="afwezig",'Reiskosten en presentie'!B19="",'Reiskosten en presentie'!B18=""),"","controle")
B45: =IF(OR('Reiskosten en presentie'!B19="afwezig",'Reiskosten en presentie'!B19="",'Reiskosten en presentie'!B18=""),"","0001 Kantoorbehoeften") | D45: =IF(OR('Reiskosten en presentie'!B19="afwezig",'Reiskosten en presentie'!B19="",'Reiskosten en presentie'!B18=""),"",'Reiskosten en presentie'!F18+'Reiskosten en presentie'!K18)
B46: =IF(OR('Reiskosten en presentie'!B19="afwezig",'Reiskosten en presentie'!B19="",'Reiskosten en presentie'!B18=""),"","0008 Reiskosten") | D46: =IF(OR('Reiskosten en presentie'!B19="afwezig",'Reiskosten en presentie'!B19="",'Reiskosten en presentie'!B18=""),"",'Reiskosten en presentie'!J18)
A48: =IF(OR('Reiskosten en presentie'!B21="afwezig",'Reiskosten en presentie'!B21="",'Reiskosten en presentie'!B20=""),"","9") | B48: =IF(OR('Reiskosten en presentie'!B21="afwezig",'Reiskosten en presentie'!B21="",'Reiskosten en presentie'!B20=""),"","Naam:") | D48: =IF(OR('Reiskosten en presentie'!B21="afwezig",'Reiskosten en presentie'!B21="",'Reiskosten en presentie'!B20=""),"",'Reiskosten en presentie'!B20)
B49: =IF(OR('Reiskosten en presentie'!B21="afwezig",'Reiskosten en presentie'!B21="",'Reiskosten en presentie'!B20=""),"","Bankrekeningnummer:") | D49: =IF(OR('Reiskosten en presentie'!B21="afwezig",'Reiskosten en presentie'!B21="",'Reiskosten en presentie'!B20=""),"",'Reiskosten en presentie'!E21) | E49: =IF(OR('Reiskosten en presentie'!B21="afwezig",'Reiskosten en presentie'!B21="",'Reiskosten en presentie'!B20=""),"",'Reiskosten en presentie'!F21) | F49: =IF(OR('Reiskosten en presentie'!B21="afwezig",'Reiskosten en presentie'!B21="",'Reiskosten en presentie'!B20=""),"",'Reiskosten en presentie'!G21) | G49: =IF(OR('Reiskosten en presentie'!B21="afwezig",'Reiskosten en presentie'!B21="",'Reiskosten en presentie'!B20=""),"",'Reiskosten en presentie'!H21) | H49: =IF(OR('Reiskosten en presentie'!B21="afwezig",'Reiskosten en presentie'!B21="",'Reiskosten en presentie'!B20=""),"",'Reiskosten en presentie'!I21) | I49: =IF(OR('Reiskosten en presentie'!B21="afwezig",'Reiskosten en presentie'!B21="",'Reiskosten en presentie'!B20=""),"","□") | J49: =IF(OR('Reiskosten en presentie'!B21="afwezig",'Reiskosten en presentie'!B21="",'Reiskosten en presentie'!B20=""),"","controle")
B50: =IF(OR('Reiskosten en presentie'!B21="afwezig",'Reiskosten en presentie'!B21="",'Reiskosten en presentie'!B20=""),"","0001 Kantoorbehoeften") | D50: =IF(OR('Reiskosten en presentie'!B21="afwezig",'Reiskosten en presentie'!B21="",'Reiskosten en presentie'!B20=""),"",'Reiskosten en presentie'!F20+'Reiskosten en presentie'!K20)
...

Sheet Opzoekblad
A1: GB-rekening | B1: Omschrijving | D1: Eerste niveau dropdown | F1: Tweede niveau dropdown | Q1: Derde niveau dropdown
A2: 801 | B2: Itembank BIO kosten | D2: Geleding | F2: Bestuur | G2: Sectie | H2: Kringcoördinatie | I2: Kring | J2: Bestuurscommissie | K2: Project | L2: Redactie | M2: Bureau | N2: Werkgroep | O2: Anders | Q2: BIO | R2: NAT | S2: NASK1 | T2: SCH | U2: NASK2 | V2: TOA
A3: 811 | B3: Redactie NVOX | D3: Bestuur | F3: AB | G3: BIO. | H3: BIO H/V | I3: BIO | J3: ARBO | L3: NVOX | N3: Diagnostische vragen | Q3: Amsterdam H/V | R3: Amsterdam H/V | S3: Amsterdam VMBO | T3: Alkmaar H/V | U3: Amsterdam VMBO | V3: Amsterdam
A4: 814 | B4: Redactie TK | D4: Bestuurscommissie | F4: DB | G4: NAT. | H4: BIO VMBO | I4: NASK1 | J4: Bovenbw | L4: TK | N4: Itembank | Q4: Amsterdam VMBO | R4: Arnhem/Nijmegen H/V | S4: Breda VMBO | T4: Amsterdam/Haarlem H/V | U4: Breda VMBO | V4: Arnhem/Nijmegen
A5: 1101 | B5: Sectie BIO. | D5: Bureau | G5: NLT. | H5: NASK1 VMBO | I5: NASK2 | J5: Duurzaamheid | Q5: Arnhem H/V | R5: Breda H/V | S5: Den Haag VMBO | T5: Arnhem/Nijmegen H/V | U5: Den Haag VMBO | V5: Breda
A6: 1106 | B6: Kringcoördinatie BIO H/V | D6: Kring | G6: SCH. | H6: NASK2 VMBO | I6: NAT | J6: Financiën | Q6: Breda H/V | R6: Den Haag H/V | S6: Friesland VMBO | T6: Breda H/V | U6: Friesland VMBO | V6: Den Haag
A7: 1107 | B7: Kringcoördinatie BIO VMBO | D7: Kringcoördinatie | G7: TECH. | H7: NAT H/V | I7: SCH | J7: Jong NVON | Q7: Den Haag H/V | R7: Eindhoven H/V | S7: Groningen VMBO | T7: Den Haag H/V | U7: Groningen VMBO | V7: Eindhoven
A8: 1127 | B8: Kring BIO Noord H/V | D8: Project | G8: TOA. | H8: SCH H/V | I8: TOA | J8: NVON-Reeks | Q8: Den Haag VMBO | R8: Kennemer H/V | S8: Kennemer VMBO | T8: Eindhoven H/V | U8: Kennemer VMBO | V8: Kennemer
A9: 1128 | B9: Kring BIO Friesland H/V | D9: Redactie | G9: VMBO. | H9: TOA | J9: Onderbw | Q9: Eindhoven H/V | R9: Limburg H/V | S9: Limburg VMBO | T9: Limburg H/V | U9: Limburg VMBO | V9: Limburg
A10: 1129 | B10: Kring BIO Zwolle H/V | D10: Sectie | J10: Ponvon | Q10: Friesland H/V | R10: Noord H/V | S10: Nijmegen VMBO | T10: Noord H/V | U10: Nijmegen VMBO | V10: Noord
A11: 1130 | B11: Kring BIO Oost H/V | D11: Anders | J11: VakbAct | Q11: Friesland VMBO | R11: Oost H/V | S11: Oost Brabant VMBO | T11: Oost H/V | U11: Oost Brabant VMBO | V11: Oost
A12: 1131 | B12: Kring BIO Arnhem H/V | J12: Wet Oriënt | Q12: Gooi-Utrecht H/V | R12: Rijnmond H/V | S12: Oost VMBO | T12: Rotterdam H/V | U12: Oost VMBO | V12: Rijnmond
A13: 1132 | B13: Kring BIO Gooi-Utrecht H/V | Q13: Gouda VMBO | R13: Utrecht H/V | S13: Rijnmond VMBO | T13: Utrecht H/V | U13: Rijnmond VMBO | V13: Utrecht
A14: 1133 | B14: Kring BIO Amsterdam H/V | Q14: Groningen VMBO | R14: Zeeland H/V | S14: Utrecht VMBO | T14: Zeeland H/V | U14: Utrecht VMBO | V14: Zeeland
A15: 1134 | B15: Kring BIO Haarlem H/V | Q15: Haarlem H/V | R15: Zwolle H/V | S15: Zeeland VMBO | T15: Zwolle H/V | U15: Zeeland VMBO | V15: Zwolle
A16: 1135 | B16: Kring BIO Kennemer H/V | Q16: Kennemer H/V | S16: Zwolle VMBO | U16: Zwolle VMBO
A17: 1136 | B17: Kring BIO Rijnland H/V | Q17: Kennemer VMBO
A18: 1137 | B18: Kring BIO Den Haag H/V | Q18: Noord H/V
A19: 1138 | B19: Kring BIO Rijnmond H/V | Q19: Oost Brabant VMBO
A20: 1139 | B20: Kring BIO Zeeland H/V | Q20: Oost Brabant/Noord Limburg H/V
A21: 1140 | B21: Kring BIO Breda H/V | Q21: Oost H/V
A22: 1141 | B22: Kring BIO Eindhoven H/V | Q22: Oost VMBO
A23: 1142 | B23: Kring BIO Oost Brabant/Noord Limburg H/V | Q23: Rijnland H/V
A24: 1143 | B24: Kring BIO Zuid-Limburg H/V | Q24: Rijnmond H/V
A25: 1158 | B25: Kring BIO Groningen VMBO | Q25: Sittard VMBO
A26: 1159 | B26: Kring BIO Friesland VMBO | Q26: Utrecht VMBO
A27: 1160 | B27: Kring BIO Zwolle/Noord Veluwe VMBO | Q27: Venlo VMBO
A28: 1161 | B28: Kring BIO Oost VMBO | Q28: West Brabant VMBO
... A34: 1167 | B34: Kring BIO Den Haag VMBO | Q34: Zwolle/Noord Veluwe VMBO
A35: 1168 | B35: Kring BIO Zeeland VMBO
A36: 1169 | B36: Kring BIO West Brabant VMBO
A37: 1170 | B37: Kring BIO Oost Brabant VMBO
A38: 1171 | B38: Kring BIO Venlo VMBO
A39: 1172 | B39: Kring BIO Sittard VMBO
A40: 1201 | B40: Sectie NAT.
A41: 1206 | B41: Kringcoördinatie NAT H/V
A42: 1207 | B42: Kringcoördinatie NASK1 VMBO
A43: 1221 | B43: Kring NAT Noord H/V
A44: 1222 | B44: Kring NAT Zwolle H/V
A45: 1223 | B45: Kring NAT Oost H/V
...
